Workbook

Sheet Sheet1
B1: 2020 | C1: 2025 | D1: 2030 | E1: 2035 | F1: 2040 | G1: 2045 | H1: 2050 | K1: wind | L1: offshore wind | M1: PV | N1: rooftop | O1: Coal CCS | P1: Coal | Q1: Gas CCS | R1: Gas | S1: Biomass
A2: wind | B2: =1405*M30 -> 1714.1 | C2: 1380.3379 | D2: 1228.3078 | E2: 1159.1908 | F2: 1090.0738 | G2: 1020.9568 | H2: 951.83978 | J2: 2025 | K2: 1380.3379 | L2: 4134.9517 | M2: 987.35235 | N2: 2518.9681 | O2: 5124.8 | P2: 3148.7 | Q2: 2504.5 | R2: 1213.1 | S2: 4363.99
A3: offshore wind | B3: =2481*M30 -> 3026.82 | C3: 4134.9517 | D3: 3130.94 | E3: 2416.9986 | F3: 2325.8848 | G3: 2257.6611 | H3: 2203.4452 | J3: 2030 | K3: 1228.3078 | L3: 3130.94 | M3: 778.88235 | N3: 2110.9266 | O3: 4811.9 | P3: 3061.2 | Q3: 2250.9 | R3: 1159.3 | S3: 4160.9495
A4: PV | B4: =1303/1.34*M30 -> 1186.3134 | C4: 987.35235 | D4: 778.88235 | E4: 570.41235 | F4: 519.39814 | G4: 468.38392 | H4: 417.3697 | J4: 2035 | K4: 1159.1908 | L4: 2416.9986 | M4: 570.41235 | N4: 1702.8852 | O4: 4499 | P4: 2973.7 | Q4: 1997.4 | R4: 1105.5 | S4: 4022.2688
A5: rooftop | B5: =2743*M30 -> 3346.46 | C5: 2518.9681 | D5: 2110.9266 | E5: 1702.8852 | F5: 1537.9479 | G5: 1373.0107 | H5: 1208.0734 | J5: 2040 | K5: 1090.0738 | L5: 2325.8848 | M5: 519.39814 | N5: 1537.9479 | O5: 4253.4 | P5: 2830.9 | Q5: 1883.3 | R5: 1059.9 | S5: 3880.1811
A6: CSP | B6: =(1910+3566*1.3/2.4)*M30 -> 4686.7317 | C6: =2126+4276*1.3/2.4 -> 4442.1667 | D6: =C6*D15/C15 -> 3594.8064 | E6: =D6*E15/D15 -> 2925.6253 | F6: =E6*F15/E15 -> 2672.3411 | G6: =F6*G15/F15 -> 2419.0837 | H6: =G6*H15/G15 -> 2165.8596 | J6: 2045 | K6: 1020.9568 | L6: 2257.6611 | M6: 468.38392 | N6: 1373.0107 | O6: 4007.8 | P6: 2688.1 | Q6: 1769.2 | R6: 1014.4 | S6: 3746.7915
A7: Coal CCS | B7: =4628*M30 -> 5646.16 | C7: 5124.8 | D7: 4811.9 | E7: 4499 | F7: 4253.4 | G7: 4007.8 | H7: 3762.1 | J7: 2050 | K7: 951.83978 | L7: 2203.4452 | M7: 417.3697 | N7: 1208.0734 | O7: 3762.1 | P7: 2545.4 | Q7: 1655.1 | R7: 968.9 | S7: 3587.8685
A8: Coal | B8: =2568*M30 -> 3132.96 | C8: 3148.7 | D8: 3061.2 | E8: 2973.7 | F8: 2830.9 | G8: 2688.1 | H8: 2545.4 | V8: wind | W8: offshore wind | X8: PV | Y8: rooftop | Z8: CSP | AA8: coal CCS | AB8: Coal | AC8: Coal IGCC | AD8: Coal IGCC CCS | AE8: Gas CCS | AF8: Gas | AG8: Biomass | AH8: CSP_base_storage | AI8: PV_base_storage
A9: Gas CCS | B9: =2399*M30 -> 2926.78 | C9: 2504.5 | D9: 2250.9 | E9: 1997.4 | F9: 1883.3 | G9: 1769.2 | H9: 1655.1 | K9: wind | L9: offshore wind | M9: PV | N9: rooftop | O9: Coal CCS | P9: Coal | Q9: Gas CCS | R9: Gas | S9: Biomass | U9: Yang | V9: 368 | W9: 678 | X9: 567 | Y9: 690 | Z9: 960 | AA9: 1212 | AB9: 672 | AC9: 1165 | AD9: 1884 | AE9: 628 | AF9: 248 | AG9: 1069 | AH9: 2270 | AI9: 1796 | AM9: =V10*5.87 -> 1743.39 | AN9: =W10*5.87 -> 3298.94 | AO9: =X10*5.87 -> 1508.59 | AP9: =Y10*5.87 -> 2711.94 | AQ9: =AA10*5.87 -> 6415.91 | AR9: =AB10*5.87 -> 3645.27 | AS9: =AE10*5.87 -> 3169.8 | AT9: =AF10*5.87 -> 1361.84 | AU9: =AG10*5.87 -> 6081.32
A10: Gas | B10: =947*1.22 -> 1155.34 | C10: 1213.1 | D10: 1159.3 | E10: 1105.5 | F10: 1059.9 | G10: 1014.4 | H10: 968.9 | J10: 2025 | K10: 1743.39 | L10: 3298.94 | M10: 1508.59 | N10: 2711.94 | O10: 6415.91 | P10: 3645.27 | Q10: 3169.8 | R10: 1361.84 | S10: 6081.32 | V10: 297 | W10: 562 | X10: 257 | Y10: 462 | Z10: 783 | AA10: 1093 | AB10: 621 | AC10: 1115 | AD10: 1793 | AE10: 540 | AF10: 232 | AG10: 1036 | AH10: 2270 | AI10: 1796 | AM10: =V11*5.87 -> 1485.11 | AN10: =W11*5.87 -> 2864.56 | AO10: =X11*5.87 -> 1232.7 | AP10: =Y11*5.87 -> 2007.54 | AQ10: =AA11*5.87 -> 5846.52 | AR10: =AB11*5.87 -> 3410.47 | AS10: =AE11*5.87 -> 2811.73 | AT10: =AF11*5.87 -> 1297.27 | AU10: =AG11*5.87 -> 5905.22
A11: Biomass | B11: =4083*M30 -> 4981.26 | C11: 4363.99 | D11: 4160.9495 | E11: 4022.2688 | F11: 3880.1811 | G11: 3746.7915 | H11: 3587.8685 | J11: 2030 | K11: 1485.11 | L11: 2864.56 | M11: 1232.7 | N11: 2007.54 | O11: 5846.52 | P11: 3410.47 | Q11: 2811.73 | R11: 1297.27 | S11: 5905.22 | V11: 253 | W11: 488 | X11: 210 | Y11: 342 | Z11: 673 | AA11: 996 | AB11: 581 | AC11: 1075 | AD11: 1716 | AE11: 479 | AF11: 221 | AG11: 1006 | AH11: 2270 | AI11: 1796 | AM11: =V12*5.87 -> 1326.62 | AN11: =W12*5.87 -> 2588.67 | AO11: =X12*5.87 -> 1074.21 | AP11: =Y12*5.87 -> 1631.86 | AQ11: =AA12*5.87 -> 5388.66 | AR11: =AB12*5.87 -> 3228.5 | AS11: =AE12*5.87 -> 2559.32 | AT11: =AF12*5.87 -> 1250.31 | AU11: =AG12*5.87 -> 5752.6
A12: Coal IGCC | B12: =4449*M30 -> 5427.78 | C12: 5539.7 | D12: 5433.9 | E12: 5328.1 | F12: 5222.3 | G12: 5116.5 | H12: 5010.7 | J12: 2035 | K12: 1326.62 | L12: 2588.67 | M12: 1074.21 | N12: 1631.86 | O12: 5388.66 | P12: 3228.5 | Q12: 2559.32 | R12: 1250.31 | S12: 5752.6 | V12: 226 | W12: 441 | X12: 183 | Y12: 278 | Z12: 604 | AA12: 918 | AB12: 550 | AC12: 1042 | AD12: 1649 | AE12: 436 | AF12: 213 | AG12: 980 | AH12: 2270 | AI12: 1796 | AM12: =V13*5.87 -> 1226.83 | AN12: =W13*5.87 -> 2412.57 | AO12: =X13*5.87 -> 992.03 | AP12: =Y13*5.87 -> 1438.15 | AQ12: =AA13*5.87 -> 5007.11 | AR12: =AB13*5.87 -> 3087.62 | AS12: =AE13*5.87 -> 2389.09 | AT12: =AF13*5.87 -> 1220.96 | AU12: =AG13*5.87 -> 5605.85
A13: Coal IGCC CCS | B13: =B12+B7-B8 -> 7940.98 | C13: 7919.2 | D13: 7766 | E13: 7612.8 | F13: 7459.7 | G13: 7306.5 | H13: 7153.3 | J13: 2040 | K13: 1226.83 | L13: 2412.57 | M13: 992.03 | N13: 1438.15 | O13: 5007.11 | P13: 3087.62 | Q13: 2389.09 | R13: 1220.96 | S13: 5605.85 | V13: 209 | W13: 411 | X13: 169 | Y13: 245 | Z13: 561 | AA13: 853 | AB13: 526 | AC13: 1015 | AD13: 1592 | AE13: 407 | AF13: 208 | AG13: 955 | AH13: 2270 | AI13: 1796 | AM13: =V14*5.87 -> 1162.26 | AN13: =W14*5.87 -> 2301.04 | AO13: =X14*5.87 -> 939.2 | AP13: =Y14*5.87 -> 1332.49 | AQ13: =AA14*5.87 -> 4701.87 | AR13: =AB14*5.87 -> 2976.09 | AS13: =AE14*5.87 -> 2265.82 | AT13: =AF14*5.87 -> 1197.48 | AU13: =AG14*5.87 -> 5476.71
A14: CSP storage | B14: =6242*M30 -> 7615.24 | C14: 6382.5935 | D14: 4775.4022 | E14: 4604.8521 | F14: 4434.3021 | G14: 4263.752 | H14: 4093.2019 | J14: 2045 | K14: 1162.26 | L14: 2301.04 | M14: 939.2 | N14: 1332.49 | O14: 4701.87 | P14: 2976.09 | Q14: 2265.82 | R14: 1197.48 | S14: 5476.71 | V14: 198 | W14: 392 | X14: 160 | Y14: 227 | Z14: 534 | AA14: 801 | AB14: 507 | AC14: 993 | AD14: 1542 | AE14: 386 | AF14: 204 | AG14: 933 | AH14: 2270 | AI14: 1796 | AM14: =V15*5.87 -> 1121.17 | AN14: =W15*5.87 -> 2224.73 | AO14: =X15*5.87 -> 915.72 | AP14: =Y15*5.87 -> 1279.66 | AQ14: =AA15*5.87 -> 4449.46 | AR14: =AB15*5.87 -> 2893.91 | AS14: =AE15*5.87 -> 2183.64 | AT14: =AF15*5.87 -> 1185.74 | AU14: =AG15*5.87 -> 5365.18
A15: PV storage | B15: =1997*M30 -> 2436.34 | C15: 2079.7097 | D15: 1682.9971 | E15: 1369.7035 | F15: 1251.1223 | G15: 1132.5536 | H15: 1014.0005 | J15: 2050 | K15: 1121.17 | L15: 2224.73 | M15: 915.72 | N15: 1279.66 | O15: 4449.46 | P15: 2893.91 | Q15: 2183.64 | R15: 1185.74 | S15: 5365.18 | V15: 191 | W15: 379 | X15: 156 | Y15: 218 | Z15: 517 | AA15: 758 | AB15: 493 | AC15: 976 | AD15: 1500 | AE15: 372 | AF15: 202 | AG15: 914 | AH15: 2270 | AI15: 1796
V17: wind | W17: offshore wind | X17: PV | Y17: rooftop | Z17: coal CCS | AA17: Coal | AB17: Gas CCS | AC17: Gas | AD17: Biomass
K18: wind | L18: offshore wind | M18: PV | N18: rooftop | O18: Coal CCS | P18: Coal | Q18: Gas CCS | R18: Gas | S18: Biomass | U18: GCAM | AC18: 262 | AD18: 1042
B19: 2020 | C19: 2025 | D19: 2030 | E19: 2035 | F19: 2040 | G19: 2045 | H19: 2050 | J19: 2025 | K19: 2177.77 | L19: 4819.27 | M19: 2154.29 | N19: 3375.25 | O19: 8857.83 | P19: 5781.95 | Q19: 3263.72 | R19: 1444.02 | S19: 5993.27 | V19: 371 | W19: 821 | X19: 367 | Y19: 575 | Z19: 1509 | AA19: 985 | AB19: 556 | AC19: 246 | AD19: 1021 | AM19: =V19*5.87 -> 2177.77 | AN19: =W19*5.87 -> 4819.27 | AO19: =X19*5.87 -> 2154.29 | AP19: =Y19*5.87 -> 3375.25 | AQ19: =Z19*5.87 -> 8857.83 | AR19: =AA19*5.87 -> 5781.95 | AS19: =AB19*5.87 -> 3263.72 | AT19: =AC19*5.87 -> 1444.02 | AU19: =AD19*5.87 -> 5993.27
A20: wind | C20: 1743.39 | D20: 1485.11 | E20: 1326.62 | F20: 1226.83 | G20: 1162.26 | H20: 1121.17 | J20: 2030 | K20: 2025.15 | L20: 4232.27 | M20: 1766.87 | N20: 2723.68 | O20: 8734.56 | P20: 5705.64 | Q20: 3152.19 | R20: 1379.45 | S20: 5875.87 | V20: 345 | W20: 721 | X20: 301 | Y20: 464 | Z20: 1488 | AA20: 972 | AB20: 537 | AC20: 235 | AD20: 1001 | AM20: =V20*5.87 -> 2025.15 | AN20: =W20*5.87 -> 4232.27 | AO20: =X20*5.87 -> 1766.87 | AP20: =Y20*5.87 -> 2723.68 | AQ20: =Z20*5.87 -> 8734.56 | AR20: =AA20*5.87 -> 5705.64 | AS20: =AB20*5.87 -> 3152.19 | AT20: =AC20*5.87 -> 1379.45 | AU20: =AD20*5.87 -> 5875.87
A21: offshore wind | C21: 3298.94 | D21: 2864.56 | E21: 2588.67 | F21: 2412.57 | G21: 2301.04 | H21: 2224.73 | J21: 2035 | K21: 1901.88 | L21: 3780.28 | M21: 1543.81 | N21: 2336.26 | O21: 8617.16 | P21: 5641.07 | Q21: 3064.14 | R21: 1332.49 | S21: 5776.08 | V21: 324 | W21: 644 | X21: 263 | Y21: 398 | Z21: 1468 | AA21: 961 | AB21: 522 | AC21: 227 | AD21: 984 | AM21: =V21*5.87 -> 1901.88 | AN21: =W21*5.87 -> 3780.28 | AO21: =X21*5.87 -> 1543.81 | AP21: =Y21*5.87 -> 2336.26 | AQ21: =Z21*5.87 -> 8617.16 | AR21: =AA21*5.87 -> 5641.07 | AS21: =AB21*5.87 -> 3064.14 | AT21: =AC21*5.87 -> 1332.49 | AU21: =AD21*5.87 -> 5776.08
A22: PV | C22: 1508.59 | D22: 1232.7 | E22: 1074.21 | F22: 992.03 | G22: 939.2 | H22: 915.72 | J22: 2040 | K22: 1807.96 | L22: 3428.08 | M22: 1408.8 | N22: 2107.33 | O22: 8511.5 | P22: 5576.5 | Q22: 2981.96 | R22: 1303.14 | S22: 5682.16 | V22: 308 | W22: 584 | X22: 240 | Y22: 359 | Z22: 1450 | AA22: 950 | AB22: 508 | AC22: 222 | AD22: 968 | AM22: =V22*5.87 -> 1807.96 | AN22: =W22*5.87 -> 3428.08 | AO22: =X22*5.87 -> 1408.8 | AP22: =Y22*5.87 -> 2107.33 | AQ22: =Z22*5.87 -> 8511.5 | AR22: =AA22*5.87 -> 5576.5 | AS22: =AB22*5.87 -> 2981.96 | AT22: =AC22*5.87 -> 1303.14 | AU22: =AD22*5.87 -> 5682.16
A23: rooftop | C23: 2711.94 | D23: 2007.54 | E23: 1631.86 | F23: 1438.15 | G23: 1332.49 | H23: 1279.66 | J23: 2045 | K23: 1731.65 | L23: 3158.06 | M23: 1326.62 | N23: 1972.32 | O23: 8405.84 | P23: 5523.67 | Q23: 2917.39 | R23: 1285.53 | S23: 5599.98 | V23: 295 | W23: 538 | X23: 226 | Y23: 336 | Z23: 1432 | AA23: 941 | AB23: 497 | AC23: 219 | AD23: 954 | AM23: =V23*5.87 -> 1731.65 | AN23: =W23*5.87 -> 3158.06 | AO23: =X23*5.87 -> 1326.62 | AP23: =Y23*5.87 -> 1972.32 | AQ23: =Z23*5.87 -> 8405.84 | AR23: =AA23*5.87 -> 5523.67 | AS23: =AB23*5.87 -> 2917.39 | AT23: =AC23*5.87 -> 1285.53 | AU23: =AD23*5.87 -> 5599.98
A24: Coal CCS | C24: 6415.91 | D24: 5846.52 | E24: 5388.66 | F24: 5007.11 | G24: 4701.87 | H24: 4449.46 | J24: 2050 | K24: 1678.82 | L24: 2946.74 | M24: 1279.66 | N24: 1896.01 | O24: 8306.05 | P24: 5470.84 | Q24: 2858.69 | R24: 1273.79 | S24: 5523.67 | V24: 286 | W24: 502 | X24: 218 | Y24: 323 | Z24: 1415 | AA24: 932 | AB24: 487 | AC24: 217 | AD24: 941 | AM24: =V24*5.87 -> 1678.82 | AN24: =W24*5.87 -> 2946.74 | AO24: =X24*5.87 -> 1279.66 | AP24: =Y24*5.87 -> 1896.01 | AQ24: =Z24*5.87 -> 8306.05 | AR24: =AA24*5.87 -> 5470.84 | AS24: =AB24*5.87 -> 2858.69 | AT24: =AC24*5.87 -> 1273.79 | AU24: =AD24*5.87 -> 5523.67
A25: Coal | C25: 3645.27 | D25: 3410.47 | E25: 3228.5 | F25: 3087.62 | G25: 2976.09 | H25: 2893.91
A26: Gas CCS | C26: 3169.8 | D26: 2811.73 | E26: 2559.32 | F26: 2389.09 | G26: 2265.82 | H26: 2183.64
A27: Gas | C27: 1361.84 | D27: 1297.27 | E27: 1250.31 | F27: 1220.96 | G27: 1197.48 | H27: 1185.74
A28: Biomass | C28: 6081.32 | D28: 5905.22 | E28: 5752.6 | F28: 5605.85 | G28: 5476.71 | H28: 5365.18
M29: 2020 to 2022
M30: 1.22
B34: 2020 | C34: 2025 | D34: 2030 | E34: 2035 | F34: 2040 | G34: 2045 | H34: 2050
A35: wind | C35: 2177.77 | D35: 2025.15 | E35: 1901.88 | F35: 1807.96 | G35: 1731.65 | H35: 1678.82
A36: offshore wind | C36: 4819.27 | D36: 4232.27 | E36: 3780.28 | F36: 3428.08 | G36: 3158.06 | H36: 2946.74
A37: PV | C37: 2154.29 | D37: 1766.87 | E37: 1543.81 | F37: 1408.8 | G37: 1326.62 | H37: 1279.66
A38: rooftop | C38: 3375.25 | D38: 2723.68 | E38: 2336.26 | F38: 2107.33 | G38: 1972.32 | H38: 1896.01
A39: Coal CCS | C39: 8857.83 | D39: 8734.56 | E39: 8617.16 | F39: 8511.5 | G39: 8405.84 | H39: 8306.05
A40: Coal | C40: 5781.95 | D40: 5705.64 | E40: 5641.07 | F40: 5576.5 | G40: 5523.67 | H40: 5470.84
A41: Gas CCS | C41: 3263.72 | D41: 3152.19 | E41: 3064.14 | F41: 2981.96 | G41: 2917.39 | H41: 2858.69
A42: Gas | C42: 1444.02 | D42: 1379.45 | E42: 1332.49 | F42: 1303.14 | G42: 1285.53 | H42: 1273.79
A43: Biomass | C43: 5993.27 | D43: 5875.87 | E43: 5776.08 | F43: 5682.16 | G43: 5599.98 | H43: 5523.67
A48: PV | F48: wind
...

Sheet Sheet2
B1: 2020 | C1: 2025 | D1: 2030 | E1: 2035 | F1: 2040 | G1: 2045 | H1: 2050 | M1: 2020 | N1: 2025 | O1: 2030 | P1: 2035 | Q1: 2040 | R1: 2045 | S1: 2050
A2: wind | B2: =1405*J3 -> 1714.1 | C2: 1380.3379 | D2: 1228.3078 | E2: 1159.1908 | F2: 1090.0738 | G2: 1020.9568 | H2: 951.83978 | J2: 2020 to 2022 | L2: wind | M2: =B2/5.87 -> 292.01022 | N2: =C2/5.87 -> 235.15126 | O2: =D2/5.87 -> 209.25175 | P2: =E2/5.87 -> 197.47713 | Q2: =F2/5.87 -> 185.70252 | R2: =G2/5.87 -> 173.9279 | S2: =H2/5.87 -> 162.15329
A3: offshore wind | B3: =2481*J3 -> 3026.82 | C3: 4134.9517 | D3: 3130.94 | E3: 2416.9986 | F3: 2325.8848 | G3: 2257.6611 | H3: 2203.4452 | J3: 1.22 | L3: offshore wind | M3: =B3/5.87 -> 515.64225 | N3: =C3/5.87 -> 704.42107 | O3: =D3/5.87 -> 533.3799 | P3: =E3/5.87 -> 411.75445 | Q3: =F3/5.87 -> 396.2325 | R3: =G3/5.87 -> 384.61007 | S3: =H3/5.87 -> 375.37397
A4: PV | B4: =1303/1.34*J3 -> 1186.3134 | C4: 987.35235 | D4: 778.88235 | E4: 570.41235 | F4: 519.39814 | G4: 468.38392 | H4: 417.3697 | L4: PV | M4: =B4/5.87 -> 202.09769 | N4: =C4/5.87 -> 168.20313 | O4: =D4/5.87 -> 132.68865 | P4: =E4/5.87 -> 97.174166 | Q4: =F4/5.87 -> 88.483498 | R4: =G4/5.87 -> 79.792831 | S4: =H4/5.87 -> 71.102164
A5: rooftop | B5: =2743*J3 -> 3346.46 | C5: 2518.9681 | D5: 2110.9266 | E5: 1702.8852 | F5: 1537.9479 | G5: 1373.0107 | H5: 1208.0734 | L5: rooftop | M5: =B5/5.87 -> 570.0954 | N5: =C5/5.87 -> 429.12573 | O5: =D5/5.87 -> 359.61271 | P5: =E5/5.87 -> 290.09969 | Q5: =F5/5.87 -> 262.00135 | R5: =G5/5.87 -> 233.90301 | S5: =H5/5.87 -> 205.80467
A6: CSP | B6: =(1910+3566*1.3/2.4)*J3 -> 4686.7317 | C6: =2126+4276*1.3/2.4 -> 4442.1667 | D6: =C6*D17/C17 -> 3323.5914 | E6: =D6*E17/D17 -> 3204.8917 | F6: =E6*F17/E17 -> 3086.192 | G6: =F6*G17/F17 -> 2967.4923 | H6: =G6*H17/G17 -> 2848.7926 | L6: CSP | M6: =B6/5.87 -> 798.42107 | N6: =C6/5.87 -> 756.75752 | O6: =D6/5.87 -> 566.19955 | P6: =E6/5.87 -> 545.97814 | Q6: =F6/5.87 -> 525.75672 | R6: =G6/5.87 -> 505.53531 | S6: =H6/5.87 -> 485.3139
A7: Coal CCS | B7: =4628*J3 -> 5646.16 | C7: 5124.8 | D7: 4811.9 | E7: 4499 | F7: 4253.4 | G7: 4007.8 | H7: 3762.1 | L7: Coal CCS | M7: =B7/5.87 -> 961.86712 | N7: =C7/5.87 -> 873.0494 | O7: =D7/5.87 -> 819.74446 | P7: =E7/5.87 -> 766.43952 | Q7: =F7/5.87 -> 724.59966 | R7: =G7/5.87 -> 682.7598 | S7: =H7/5.87 -> 640.9029
A8: Coal | B8: =3628*J3 -> 4426.16 | C8: 3148.7 | D8: 3061.2 | E8: 2973.7 | F8: 2830.9 | G8: 2688.1 | H8: 2545.4 | L8: Coal | M8: =B8/5.87 -> 754.03066 | N8: =C8/5.87 -> 536.40545 | O8: =D8/5.87 -> 521.49915 | P8: =E8/5.87 -> 506.59284 | Q8: =F8/5.87 -> 482.26576 | R8: =G8/5.87 -> 457.93867 | S8: =H8/5.87 -> 433.62862
A9: Coal IGCC | B9: =4449*J3 -> 5427.78 | C9: 5539.7 | D9: 5433.9 | E9: 5328.1 | F9: 5222.3 | G9: 5116.5 | H9: 5010.7 | L9: Coal IGCC | M9: =B9/5.87 -> 924.6644 | N9: =C9/5.87 -> 943.73083 | O9: =D9/5.87 -> 925.70698 | P9: =E9/5.87 -> 907.68313 | Q9: =F9/5.87 -> 889.65928 | R9: =G9/5.87 -> 871.63543 | S9: =H9/5.87 -> 853.61158
A10: Coal IGCC CCS | B10: =B9+B7-B8 -> 6647.78 | C10: 7919.2 | D10: 7766 | E10: 7612.8 | F10: 7459.7 | G10: 7306.5 | H10: 7153.3 | L10: Coal IGCC CCS | M10: =B10/5.87 -> 1132.5009 | N10: =C10/5.87 -> 1349.0971 | O10: =D10/5.87 -> 1322.9983 | P10: =E10/5.87 -> 1296.8995 | Q10: =F10/5.87 -> 1270.8177 | R10: =G10/5.87 -> 1244.7189 | S10: =H10/5.87 -> 1218.6201
A11: Gas CCS | B11: =2399*J3 -> 2926.78 | C11: 2504.5 | D11: 2250.9 | E11: 1997.4 | F11: 1883.3 | G11: 1769.2 | H11: 1655.1 | L11: Gas CCS | M11: =B11/5.87 -> 498.59966 | N11: =C11/5.87 -> 426.66099 | O11: =D11/5.87 -> 383.45826 | P11: =E11/5.87 -> 340.27257 | Q11: =F11/5.87 -> 320.83475 | R11: =G11/5.87 -> 301.39693 | S11: =H11/5.87 -> 281.95911
A12: Gas | B12: =947*1.22 -> 1155.34 | C12: 1213.1 | D12: 1159.3 | E12: 1105.5 | F12: 1059.9 | G12: 1014.4 | H12: 968.9 | L12: Gas | M12: =B12/5.87 -> 196.82112 | N12: =C12/5.87 -> 206.66099 | O12: =D12/5.87 -> 197.49574 | P12: =E12/5.87 -> 188.33049 | Q12: =F12/5.87 -> 180.56218 | R12: =G12/5.87 -> 172.8109 | S12: =H12/5.87 -> 165.05963
A13: Biomass | B13: =4083*J3 -> 4981.26 | C13: 4363.99 | D13: 4160.9495 | E13: 4022.2688 | F13: 3880.1811 | G13: 3746.7915 | H13: 3587.8685 | L13: Biomass | M13: =B13/5.87 -> 848.59625 | N13: =C13/5.87 -> 743.43952 | O13: =D13/5.87 -> 708.85 | P13: =E13/5.87 -> 685.22467 | Q13: =F13/5.87 -> 661.01893 | R13: =G13/5.87 -> 638.29498 | S13: =H13/5.87 -> 611.2212
A14: Biomass CCS | B14: =B13*B65/B64 -> 9221.6216 | C14: =C13*C65/C64 -> 7914.9973 | D14: =D13*D65/D64 -> 7395.4053 | E14: =E13*E65/E64 -> 6997.9268 | F14: =F13*F65/F64 -> 6626.7806 | G14: =G13*G65/G64 -> 6276.7794 | H14: =H13*H65/H64 -> 5899.9631 | L14: Biomass CCS | M14: =B14/5.87 -> 1570.9747 | N14: =C14/5.87 -> 1348.3811 | O14: =D14/5.87 -> 1259.8646 | P14: =E14/5.87 -> 1192.1511 | Q14: =F14/5.87 -> 1128.9234 | R14: =G14/5.87 -> 1069.298 | S14: =H14/5.87 -> 1005.1045
A15: Biomass IGCC | B15: =B13*B68/B64 -> 7245.8927 | C15: =C13*C68/C64 -> 6238.4838 | D15: =D13*D68/D64 -> 5852.6278 | E15: =E13*E68/E64 -> 5561.4023 | F15: =F13*F68/F64 -> 5285.985 | G15: =G13*G68/G64 -> 5031.8647 | H15: =H13*H68/H64 -> 4741.9531 | L15: Biomass IGCC | M15: =B15/5.87 -> 1234.394 | N15: =C15/5.87 -> 1062.7741 | O15: =D15/5.87 -> 997.04051 | P15: =E15/5.87 -> 947.42798 | Q15: =F15/5.87 -> 900.50852 | R15: =G15/5.87 -> 857.21716 | S15: =H15/5.87 -> 807.82846
A16: Biomass IGCC CCS | B16: =B13*B69/B64 -> 10512.369 | C16: =C13*C69/C64 -> 8938.5973 | D16: =D13*D69/D64 -> 8272.2655 | E16: =E13*E69/E64 -> 7757.2327 | F16: =F13*F69/F64 -> 7276.8633 | G16: =G13*G69/G64 -> 6830.9672 | H16: =H13*H69/H64 -> 6359.2417 | L16: Biomass IGCC CCS | M16: =B16/5.87 -> 1790.8636 | N16: =C16/5.87 -> 1522.7593 | O16: =D16/5.87 -> 1409.2445 | P16: =E16/5.87 -> 1321.5047 | Q16: =F16/5.87 -> 1239.6701 | R16: =G16/5.87 -> 1163.7082 | S16: =H16/5.87 -> 1083.3461
A17: CSP storage | B17: =6242*J3 -> 7615.24 | C17: 6382.5935 | D17: 4775.4022 | E17: 4604.8521 | F17: 4434.3021 | G17: 4263.752 | H17: 4093.2019 | L17: CSP storage | M17: =B17/5.87 -> 1297.3152 | N17: =C17/5.87 -> 1087.3243 | O17: =D17/5.87 -> 813.52678 | P17: =E17/5.87 -> 784.47226 | Q17: =F17/5.87 -> 755.41773 | R17: =G17/5.87 -> 726.3632 | S17: =H17/5.87 -> 697.30867
A18: PV storage | B18: =1997*J3/1.34 -> 1818.1642 | C18: 1552.0222 | D18: 1255.968 | E18: 1022.1668 | F18: 933.67335 | G18: 845.18923 | H18: 756.71677 | L18: PV storage | M18: =B18/5.87 -> 309.73836 | N18: =C18/5.87 -> 264.399 | O18: =D18/5.87 -> 213.96388 | P18: =E18/5.87 -> 174.13403 | Q18: =F18/5.87 -> 159.05849 | R18: =G18/5.87 -> 143.98454 | S18: =H18/5.87 -> 128.91257
A19: wind storage | B19: =B2+B18-B4 -> 2345.9507 | C19: =C2+C18-C4 -> 1945.0077 | D19: =D2+D18-D4 -> 1705.3934 | E19: =E2+E18-E4 -> 1610.9452 | F19: =F2+F18-F4 -> 1504.349 | G19: =G2+G18-G4 -> 1397.7621 | H19: =H2+H18-H4 -> 1291.1868 | L19: wind storage | M19: =B19/5.87 -> 399.65089 | N19: =C19/5.87 -> 331.34713 | O19: =D19/5.87 -> 290.52698 | P19: =E19/5.87 -> 274.437 | Q19: =F19/5.87 -> 256.27751 | R19: =G19/5.87 -> 238.11961 | S19: =H19/5.87 -> 219.96369
A20: Gas CT | B20: =841*J3 -> 1026.02 | C20: 1319.3962 | D20: 1270.476 | E20: 1221.4444 | F20: 1172.5242 | G20: 1123.604 | H20: 1074.5724 | L20: Gas CT | M20: =B20/5.87 -> 174.79046 | N20: =C20/5.87 -> 224.76936 | O20: =D20/5.87 -> 216.43543 | P20: =E20/5.87 -> 208.08252 | Q20: =F20/5.87 -> 199.74859 | R20: =G20/5.87 -> 191.41465 | S20: =H20/5.87 -> 183.06174
M21: =B21/5.87 -> 0 | N21: =C21/5.87 -> 0 | O21: =D21/5.87 -> 0 | P21: =E21/5.87 -> 0 | Q21: =F21/5.87 -> 0 | R21: =G21/5.87 -> 0 | S21: =H21/5.87 -> 0
M22: =B22/5.87 -> 0 | N22: =C22/5.87 -> 0 | O22: =D22/5.87 -> 0 | P22: =E22/5.87 -> 0 | Q22: =F22/5.87 -> 0 | R22: =G22/5.87 -> 0 | S22: =H22/5.87 -> 0
M23: =B23/5.87 -> 0 | N23: =C23/5.87 -> 0 | O23: =D23/5.87 -> 0 | P23: =E23/5.87 -> 0 | Q23: =F23/5.87 -> 0 | R23: =G23/5.87 -> 0 | S23: =H23/5.87 -> 0
A33: Yang | B33: wind | C33: offshore wind | D33: PV | E33: rooftop | F33: CSP | G33: coal CCS | H33: Coal | I33: Coal IGCC | J33: Coal IGCC CCS | K33: Gas CCS | L33: Gas | M33: Biomass | N33: Biomas CCS | O33: CSP_base_storage | P33: PV_base_storage | Q33: Biomass IGCC | R33: Biomass IGCC CCS | S33: Gas CT
A34: 2020 | B34: 368 | C34: 678 | D34: 567 | E34: 690 | F34: 960 | G34: 1212 | H34: 672 | I34: 1165 | J34: 1884 | K34: 628 | L34: 248 | M34: 1069 | N34: 1979 | O34: 2270 | P34: 1796 | Q34: 1555 | R34: 2256 | S34: 220
A35: 2025 | B35: 297 | C35: 562 | D35: 257 | E35: 462 | F35: 783 | G35: 1093 | H35: 621 | I35: 1115 | J35: 1793 | K35: 540 | L35: 232 | M35: 1036 | N35: 1879 | O35: 2270 | P35: 1796 | Q35: 1481 | R35: 2122 | S35: 201
A36: 2030 | B36: 253 | C36: 488 | D36: 210 | E36: 342 | F36: 673 | G36: 996 | H36: 581 | I36: 1075 | J36: 1716 | K36: 479 | L36: 221 | M36: 1006 | N36: 1788 | O36: 2270 | P36: 1796 | Q36: 1415 | R36: 2000 | S36: 189
A37: 2035 | B37: 226 | C37: 441 | D37: 183 | E37: 278 | F37: 604 | G37: 918 | H37: 550 | I37: 1042 | J37: 1649 | K37: 436 | L37: 213 | M37: 980 | N37: 1705 | O37: 2270 | P37: 1796 | Q37: 1355 | R37: 1890 | S37: 181
A38: 2040 | B38: 209 | C38: 411 | D38: 169 | E38: 245 | F38: 561 | G38: 853 | H38: 526 | I38: 1015 | J38: 1592 | K38: 407 | L38: 208 | M38: 955 | N38: 1631 | O38: 2270 | P38: 1796 | Q38: 1301 | R38: 1791 | S38: 176
A39: 2045 | B39: 198 | C39: 392 | D39: 160 | E39: 227 | F39: 534 | G39: 801 | H39: 507 | I39: 993 | J39: 1542 | K39: 386 | L39: 204 | M39: 933 | N39: 1563 | O39: 2270 | P39: 1796 | Q39: 1253 | R39: 1701 | S39: 172
A40: 2050 | B40: 191 | C40: 379 | D40: 156 | E40: 218 | F40: 517 | G40: 758 | H40: 493 | I40: 976 | J40: 1500 | K40: 372 | L40: 202 | M40: 914 | N40: 1503 | O40: 2270 | P40: 1796 | Q40: 1208 | R40: 1620 | S40: 170
B42: wind | C42: offshore wind | D42: PV | E42: rooftop | F42: CSP | G42: coal CCS | H42: Coal | I42: Coal IGCC | J42: Coal IGCC CCS | K42: Gas CCS | L42: Gas | M42: Biomass | N42: CSP_base_storage | O42: PV_base_storage
B43: =B34*5.87 -> 2160.16 | C43: =C34*5.87 -> 3979.86 | D43: =D34*5.87 -> 3328.29 | E43: =E34*5.87 -> 4050.3 | F43: =F34*5.87 -> 5635.2 | G43: =G34*5.87 -> 7114.44 | H43: =H34*5.87 -> 3944.64 | I43: =I34*5.87 -> 6838.55 | ... M43: =M34*5.87 -> 6275.03 | N43: =O34*5.87 -> 13324.9 | O43: =P34*5.87 -> 10542.52
B44: =B35*5.87 -> 1743.39 | C44: =C35*5.87 -> 3298.94 | D44: =D35*5.87 -> 1508.59 | E44: =E35*5.87 -> 2711.94 | F44: =F35*5.87 -> 4596.21 | G44: =G35*5.87 -> 6415.91 | H44: =H35*5.87 -> 3645.27 | I44: =I35*5.87 -> 6545.05 | ... M44: =M35*5.87 -> 6081.32 | N44: =O35*5.87 -> 13324.9 | O44: =P35*5.87 -> 10542.52
B45: =B36*5.87 -> 1485.11 | C45: =C36*5.87 -> 2864.56 | D45: =D36*5.87 -> 1232.7 | E45: =E36*5.87 -> 2007.54 | F45: =F36*5.87 -> 3950.51 | G45: =G36*5.87 -> 5846.52 | H45: =H36*5.87 -> 3410.47 | I45: =I36*5.87 -> 6310.25 | ... M45: =M36*5.87 -> 5905.22 | N45: =O36*5.87 -> 13324.9 | O45: =P36*5.87 -> 10542.52
B46: =B37*5.87 -> 1326.62 | C46: =C37*5.87 -> 2588.67 | D46: =D37*5.87 -> 1074.21 | E46: =E37*5.87 -> 1631.86 | F46: =F37*5.87 -> 3545.48 | G46: =G37*5.87 -> 5388.66 | H46: =H37*5.87 -> 3228.5 | I46: =I37*5.87 -> 6116.54 | ... M46: =M37*5.87 -> 5752.6 | N46: =O37*5.87 -> 13324.9 | O46: =P37*5.87 -> 10542.52
B47: =B38*5.87 -> 1226.83 | C47: =C38*5.87 -> 2412.57 | D47: =D38*5.87 -> 992.03 | E47: =E38*5.87 -> 1438.15 | F47: =F38*5.87 -> 3293.07 | G47: =G38*5.87 -> 5007.11 | H47: =H38*5.87 -> 3087.62 | I47: =I38*5.87 -> 5958.05 | ... M47: =M38*5.87 -> 5605.85 | N47: =O38*5.87 -> 13324.9 | O47: =P38*5.87 -> 10542.52
B48: =B39*5.87 -> 1162.26 | C48: =C39*5.87 -> 2301.04 | D48: =D39*5.87 -> 939.2 | E48: =E39*5.87 -> 1332.49 | F48: =F39*5.87 -> 3134.58 | G48: =G39*5.87 -> 4701.87 | H48: =H39*5.87 -> 2976.09 | I48: =I39*5.87 -> 5828.91 | ... M48: =M39*5.87 -> 5476.71 | N48: =O39*5.87 -> 13324.9 | O48: =P39*5.87 -> 10542.52
B49: =B40*5.87 -> 1121.17 | C49: =C40*5.87 -> 2224.73 | D49: =D40*5.87 -> 915.72 | E49: =E40*5.87 -> 1279.66 | F49: =F40*5.87 -> 3034.79 | G49: =G40*5.87 -> 4449.46 | H49: =H40*5.87 -> 2893.91 | I49: =I40*5.87 -> 5729.12 | ... M49: =M40*5.87 -> 5365.18 | N49: =O40*5.87 -> 13324.9 | O49: =P40*5.87 -> 10542.52
A52: Yang | B52: 2020 | C52: 2025 | D52: 2030 | E52: 2035 | F52: 2040 | G52: 2045 | H52: 2050
...

Sheet technology_cost
A1: technology | B1: 2020 | C1: 2025 | D1: 2030 | E1: 2035 | F1: 2040 | G1: 2045 | H1: 2050
A2: biomass_base_conv | B2: =Sheet2!M$13 -> 848.59625 | C2: =Sheet2!N$13 -> 743.43952 | D2: =Sheet2!O$13 -> 708.85 | E2: =Sheet2!P$13 -> 685.22467 | F2: =Sheet2!Q$13 -> 661.01893 | G2: =Sheet2!R$13 -> 638.29498 | H2: =Sheet2!S$13 -> 611.2212
A3: biomass_base_conv_CCS | B3: =Sheet2!M$14 -> 1570.9747 | C3: =Sheet2!N$14 -> 1348.3811 | D3: =Sheet2!O$14 -> 1259.8646 | E3: =Sheet2!P$14 -> 1192.1511 | F3: =Sheet2!Q$14 -> 1128.9234 | G3: =Sheet2!R$14 -> 1069.298 | H3: =Sheet2!S$14 -> 1005.1045
A4: biomass_base_IGCC | B4: =Sheet2!M$15 -> 1234.394 | C4: =Sheet2!N$15 -> 1062.7741 | D4: =Sheet2!O$15 -> 997.04051 | E4: =Sheet2!P$15 -> 947.42798 | F4: =Sheet2!Q$15 -> 900.50852 | G4: =Sheet2!R$15 -> 857.21716 | H4: =Sheet2!S$15 -> 807.82846
A5: biomass_base_IGCC_CCS | B5: =Sheet2!M$16 -> 1790.8636 | C5: =Sheet2!N$16 -> 1522.7593 | D5: =Sheet2!O$16 -> 1409.2445 | E5: =Sheet2!P$16 -> 1321.5047 | F5: =Sheet2!Q$16 -> 1239.6701 | G5: =Sheet2!R$16 -> 1163.7082 | H5: =Sheet2!S$16 -> 1083.3461
A6: coal_base_conv_pul | B6: =Sheet2!M$8 -> 754.03066 | C6: =Sheet2!N$8 -> 536.40545 | D6: =Sheet2!O$8 -> 521.49915 | E6: =Sheet2!P$8 -> 506.59284 | F6: =Sheet2!Q$8 -> 482.26576 | G6: =Sheet2!R$8 -> 457.93867 | H6: =Sheet2!S$8 -> 433.62862
A7: coal_base_conv_pul_CCS | B7: =Sheet2!M$7 -> 961.86712 | C7: =Sheet2!N$7 -> 873.0494 | D7: =Sheet2!O$7 -> 819.74446 | E7: =Sheet2!P$7 -> 766.43952 | F7: =Sheet2!Q$7 -> 724.59966 | G7: =Sheet2!R$7 -> 682.7598 | H7: =Sheet2!S$7 -> 640.9029
A8: coal_base_IGCC | B8: =Sheet2!M$9 -> 924.6644 | C8: =Sheet2!N$9 -> 943.73083 | D8: =Sheet2!O$9 -> 925.70698 | E8: =Sheet2!P$9 -> 907.68313 | F8: =Sheet2!Q$9 -> 889.65928 | G8: =Sheet2!R$9 -> 871.63543 | H8: =Sheet2!S$9 -> 853.61158
A9: coal_base_IGCC_CCS | B9: =Sheet2!M$10 -> 1132.5009 | C9: =Sheet2!N$10 -> 1349.0971 | D9: =Sheet2!O$10 -> 1322.9983 | E9: =Sheet2!P$10 -> 1296.8995 | F9: =Sheet2!Q$10 -> 1270.8177 | G9: =Sheet2!R$10 -> 1244.7189 | H9: =Sheet2!S$10 -> 1218.6201
A10: gas_base_CC | B10: =Sheet2!M$12 -> 196.82112 | C10: =Sheet2!N$12 -> 206.66099 | D10: =Sheet2!O$12 -> 197.49574 | E10: =Sheet2!P$12 -> 188.33049 | F10: =Sheet2!Q$12 -> 180.56218 | G10: =Sheet2!R$12 -> 172.8109 | H10: =Sheet2!S$12 -> 165.05963
A11: gas_base_CC_CCS | B11: =Sheet2!M$11 -> 498.59966 | C11: =Sheet2!N$11 -> 426.66099 | D11: =Sheet2!O$11 -> 383.45826 | E11: =Sheet2!P$11 -> 340.27257 | F11: =Sheet2!Q$11 -> 320.83475 | G11: =Sheet2!R$11 -> 301.39693 | H11: =Sheet2!S$11 -> 281.95911
A12: biomass_int_conv | B12: =Sheet2!M$13 -> 848.59625 | C12: =Sheet2!N$13 -> 743.43952 | D12: =Sheet2!O$13 -> 708.85 | E12: =Sheet2!P$13 -> 685.22467 | F12: =Sheet2!Q$13 -> 661.01893 | G12: =Sheet2!R$13 -> 638.29498 | H12: =Sheet2!S$13 -> 611.2212
A13: biomass_int_conv_CCS | B13: =Sheet2!M$14 -> 1570.9747 | C13: =Sheet2!N$14 -> 1348.3811 | D13: =Sheet2!O$14 -> 1259.8646 | E13: =Sheet2!P$14 -> 1192.1511 | F13: =Sheet2!Q$14 -> 1128.9234 | G13: =Sheet2!R$14 -> 1069.298 | H13: =Sheet2!S$14 -> 1005.1045
A14: biomass_int_IGCC | B14: =Sheet2!M$15 -> 1234.394 | C14: =Sheet2!N$15 -> 1062.7741 | D14: =Sheet2!O$15 -> 997.04051 | E14: =Sheet2!P$15 -> 947.42798 | F14: =Sheet2!Q$15 -> 900.50852 | G14: =Sheet2!R$15 -> 857.21716 | H14: =Sheet2!S$15 -> 807.82846
A15: biomass_int_IGCC_CCS | B15: =Sheet2!M$16 -> 1790.8636 | C15: =Sheet2!N$16 -> 1522.7593 | D15: =Sheet2!O$16 -> 1409.2445 | E15: =Sheet2!P$16 -> 1321.5047 | F15: =Sheet2!Q$16 -> 1239.6701 | G15: =Sheet2!R$16 -> 1163.7082 | H15: =Sheet2!S$16 -> 1083.3461
A16: coal_int_conv_pul | B16: =Sheet2!M$8 -> 754.03066 | C16: =Sheet2!N$8 -> 536.40545 | D16: =Sheet2!O$8 -> 521.49915 | E16: =Sheet2!P$8 -> 506.59284 | F16: =Sheet2!Q$8 -> 482.26576 | G16: =Sheet2!R$8 -> 457.93867 | H16: =Sheet2!S$8 -> 433.62862
A17: coal_int_conv_pul_CCS | B17: =Sheet2!M$7 -> 961.86712 | C17: =Sheet2!N$7 -> 873.0494 | D17: =Sheet2!O$7 -> 819.74446 | E17: =Sheet2!P$7 -> 766.43952 | F17: =Sheet2!Q$7 -> 724.59966 | G17: =Sheet2!R$7 -> 682.7598 | H17: =Sheet2!S$7 -> 640.9029
A18: coal_int_IGCC | B18: =Sheet2!M$9 -> 924.6644 | C18: =Sheet2!N$9 -> 943.73083 | D18: =Sheet2!O$9 -> 925.70698 | E18: =Sheet2!P$9 -> 907.68313 | F18: =Sheet2!Q$9 -> 889.65928 | G18: =Sheet2!R$9 -> 871.63543 | H18: =Sheet2!S$9 -> 853.61158
A19: coal_int_IGCC_CCS | B19: =Sheet2!M$10 -> 1132.5009 | C19: =Sheet2!N$10 -> 1349.0971 | D19: =Sheet2!O$10 -> 1322.9983 | E19: =Sheet2!P$10 -> 1296.8995 | F19: =Sheet2!Q$10 -> 1270.8177 | G19: =Sheet2!R$10 -> 1244.7189 | H19: =Sheet2!S$10 -> 1218.6201
A20: gas_int_CC | B20: =Sheet2!M$12 -> 196.82112 | C20: =Sheet2!N$12 -> 206.66099 | D20: =Sheet2!O$12 -> 197.49574 | E20: =Sheet2!P$12 -> 188.33049 | F20: =Sheet2!Q$12 -> 180.56218 | G20: =Sheet2!R$12 -> 172.8109 | H20: =Sheet2!S$12 -> 165.05963
A21: gas_int_CC_CCS | B21: =Sheet2!M$11 -> 498.59966 | C21: =Sheet2!N$11 -> 426.66099 | D21: =Sheet2!O$11 -> 383.45826 | E21: =Sheet2!P$11 -> 340.27257 | F21: =Sheet2!Q$11 -> 320.83475 | G21: =Sheet2!R$11 -> 301.39693 | H21: =Sheet2!S$11 -> 281.95911
A22: coal_peal_conv_pul | B22: =Sheet2!M$8 -> 754.03066 | C22: =Sheet2!N$8 -> 536.40545 | D22: =Sheet2!O$8 -> 521.49915 | E22: =Sheet2!P$8 -> 506.59284 | F22: =Sheet2!Q$8 -> 482.26576 | G22: =Sheet2!R$8 -> 457.93867 | H22: =Sheet2!S$8 -> 433.62862
A23: gas_peak_CC | B23: =Sheet2!M$12 -> 196.82112 | C23: =Sheet2!N$12 -> 206.66099 | D23: =Sheet2!O$12 -> 197.49574 | E23: =Sheet2!P$12 -> 188.33049 | F23: =Sheet2!Q$12 -> 180.56218 | G23: =Sheet2!R$12 -> 172.8109 | H23: =Sheet2!S$12 -> 165.05963
A24: gas_peak_CC_CCS | B24: =Sheet2!M$11 -> 498.59966 | C24: =Sheet2!N$11 -> 426.66099 | D24: =Sheet2!O$11 -> 383.45826 | E24: =Sheet2!P$11 -> 340.27257 | F24: =Sheet2!Q$11 -> 320.83475 | G24: =Sheet2!R$11 -> 301.39693 | H24: =Sheet2!S$11 -> 281.95911
A25: gas_peak_steam/CT | B25: =Sheet2!M20 -> 174.79046 | C25: =Sheet2!N20 -> 224.76936 | D25: =Sheet2!O20 -> 216.43543 | E25: =Sheet2!P20 -> 208.08252 | F25: =Sheet2!Q20 -> 199.74859 | G25: =Sheet2!R20 -> 191.41465 | H25: =Sheet2!S20 -> 183.06174
A26: rooftop_pv | B26: =Sheet2!M5 -> 570.0954 | C26: =Sheet2!N5 -> 429.12573 | D26: =Sheet2!O5 -> 359.61271 | E26: =Sheet2!P5 -> 290.09969 | F26: =Sheet2!Q5 -> 262.00135 | G26: =Sheet2!R5 -> 233.90301 | H26: =Sheet2!S5 -> 205.80467
A27: PV_int | B27: =Sheet2!M$4 -> 202.09769 | C27: =Sheet2!N$4 -> 168.20313 | D27: =Sheet2!O$4 -> 132.68865 | E27: =Sheet2!P$4 -> 97.174166 | F27: =Sheet2!Q$4 -> 88.483498 | G27: =Sheet2!R$4 -> 79.792831 | H27: =Sheet2!S$4 -> 71.102164
A28: PV_subpeak | B28: =Sheet2!M$4 -> 202.09769 | C28: =Sheet2!N$4 -> 168.20313 | D28: =Sheet2!O$4 -> 132.68865 | E28: =Sheet2!P$4 -> 97.174166 | F28: =Sheet2!Q$4 -> 88.483498 | G28: =Sheet2!R$4 -> 79.792831 | H28: =Sheet2!S$4 -> 71.102164
A29: PV_peak | B29: =Sheet2!M$4 -> 202.09769 | C29: =Sheet2!N$4 -> 168.20313 | D29: =Sheet2!O$4 -> 132.68865 | E29: =Sheet2!P$4 -> 97.174166 | F29: =Sheet2!Q$4 -> 88.483498 | G29: =Sheet2!R$4 -> 79.792831 | H29: =Sheet2!S$4 -> 71.102164
A30: wind_base | B30: =Sheet2!M2 -> 292.01022 | C30: =Sheet2!N2 -> 235.15126 | D30: =Sheet2!O2 -> 209.25175 | E30: =Sheet2!P2 -> 197.47713 | F30: =Sheet2!Q2 -> 185.70252 | G30: =Sheet2!R2 -> 173.9279 | H30: =Sheet2!S2 -> 162.15329
A31: wind_base_offshore | B31: =Sheet2!M3 -> 515.64225 | C31: =Sheet2!N3 -> 704.42107 | D31: =Sheet2!O3 -> 533.3799 | E31: =Sheet2!P3 -> 411.75445 | F31: =Sheet2!Q3 -> 396.2325 | G31: =Sheet2!R3 -> 384.61007 | H31: =Sheet2!S3 -> 375.37397
A32: wind_int | B32: =Sheet2!M$2 -> 292.01022 | C32: =Sheet2!N$2 -> 235.15126 | D32: =Sheet2!O$2 -> 209.25175 | E32: =Sheet2!P$2 -> 197.47713 | F32: =Sheet2!Q$2 -> 185.70252 | G32: =Sheet2!R$2 -> 173.9279 | H32: =Sheet2!S$2 -> 162.15329
A33: wind_subpeak | B33: =Sheet2!M$2 -> 292.01022 | C33: =Sheet2!N$2 -> 235.15126 | D33: =Sheet2!O$2 -> 209.25175 | E33: =Sheet2!P$2 -> 197.47713 | F33: =Sheet2!Q$2 -> 185.70252 | G33: =Sheet2!R$2 -> 173.9279 | H33: =Sheet2!S$2 -> 162.15329
A34: CSP_int | B34: =Sheet2!M$6 -> 798.42107 | C34: =Sheet2!N$6 -> 756.75752 | D34: =Sheet2!O$6 -> 566.19955 | E34: =Sheet2!P$6 -> 545.97814 | F34: =Sheet2!Q$6 -> 525.75672 | G34: =Sheet2!R$6 -> 505.53531 | H34: =Sheet2!S$6 -> 485.3139
A35: CSP_peak | B35: =Sheet2!M$6 -> 798.42107 | C35: =Sheet2!N$6 -> 756.75752 | D35: =Sheet2!O$6 -> 566.19955 | E35: =Sheet2!P$6 -> 545.97814 | F35: =Sheet2!Q$6 -> 525.75672 | G35: =Sheet2!R$6 -> 505.53531 | H35: =Sheet2!S$6 -> 485.3139
A36: CSP_subpeak | B36: =Sheet2!M$6 -> 798.42107 | C36: =Sheet2!N$6 -> 756.75752 | D36: =Sheet2!O$6 -> 566.19955 | E36: =Sheet2!P$6 -> 545.97814 | F36: =Sheet2!Q$6 -> 525.75672 | G36: =Sheet2!R$6 -> 505.53531 | H36: =Sheet2!S$6 -> 485.3139
